Workbook

Sheet 요약
A1: 2026년 카드 사용기록 요약
A2: 월별 탭은 실제 사용일 기준이며, 2025년 12월 이월 거래는 별도 탭에 분리했습니다.
A4: 월 | B4: 구매 지출 합계 | C4: 환불/크레딧 합계 | D4: 카드대금 결제 합계 | E4: 순액 | F4: 거래 수
A5: 01월 | B5: ='01월'!$B$3 | C5: ='01월'!$B$4 | D5: ='01월'!$B$5 | E5: ='01월'!$B$6 | F5: ='01월'!$B$7
A6: 02월 | B6: ='02월'!$B$3 | C6: ='02월'!$B$4 | D6: ='02월'!$B$5 | E6: ='02월'!$B$6 | F6: ='02월'!$B$7
A7: 03월 | B7: ='03월'!$B$3 | C7: ='03월'!$B$4 | D7: ='03월'!$B$5 | E7: ='03월'!$B$6 | F7: ='03월'!$B$7
A8: 04월 | B8: ='04월'!$B$3 | C8: ='04월'!$B$4 | D8: ='04월'!$B$5 | E8: ='04월'!$B$6 | F8: ='04월'!$B$7
A9: 05월 | B9: ='05월'!$B$3 | C9: ='05월'!$B$4 | D9: ='05월'!$B$5 | E9: ='05월'!$B$6 | F9: ='05월'!$B$7
A10: 06월 | B10: ='06월'!$B$3 | C10: ='06월'!$B$4 | D10: ='06월'!$B$5 | E10: ='06월'!$B$6 | F10: ='06월'!$B$7
A11: 07월 | B11: ='07월'!$B$3 | C11: ='07월'!$B$4 | D11: ='07월'!$B$5 | E11: ='07월'!$B$6 | F11: ='07월'!$B$7
A12: 08월 | B12: ='08월'!$B$3 | C12: ='08월'!$B$4 | D12: ='08월'!$B$5 | E12: ='08월'!$B$6 | F12: ='08월'!$B$7
A13: 09월 | B13: ='09월'!$B$3 | C13: ='09월'!$B$4 | D13: ='09월'!$B$5 | E13: ='09월'!$B$6 | F13: ='09월'!$B$7
A14: 10월 | B14: ='10월'!$B$3 | C14: ='10월'!$B$4 | D14: ='10월'!$B$5 | E14: ='10월'!$B$6 | F14: ='10월'!$B$7
A15: 11월 | B15: ='11월'!$B$3 | C15: ='11월'!$B$4 | D15: ='11월'!$B$5 | E15: ='11월'!$B$6 | F15: ='11월'!$B$7
A16: 12월 | B16: ='12월'!$B$3 | C16: ='12월'!$B$4 | D16: ='12월'!$B$5 | E16: ='12월'!$B$6 | F16: ='12월'!$B$7
A19: 기본 대분류별 구매 지출 | D19: 사용 방법
A20: 대분류 | B20: 구매 지출 합계 | D20: 1) 각 월 탭에서 필터로 상점/분류를 확인하세요.
A21: 교통/주유 | B21: 394.68 | D21: 2) 직접 바꾸고 싶은 분류는 사용자_대분류/사용자_세부분류 열에 입력하세요.
A22: 보험 | B22: 440 | D22: 3) 원본_대분류/원본_세부분류는 자동 분류 결과라 비교용으로 남겨두었습니다.
A23: 식료품/생활용품 | B23: 1279.72 | D23: 4) 원본금액이나 거래유형을 바꾸면 월 탭 상단의 합계가 엑셀에서 다시 계산됩니다.
A24: 엔터테인먼트 | B24: 64.46
A25: 온라인쇼핑 | B25: 583.29

Sheet 분류목록
A1: 대분류 | B1: 세부분류 | D1: 분류 기준
A2: 식료품/생활용품 | B2: Costco 매장 | D2: Costco Gas -> 교통/주유 / 주유
A3: 교통/주유 | B3: Costco 온라인 | D3: Costco WHSE -> 식료품/생활용품 / Costco 매장
A4: 온라인쇼핑 | B4: 주유 | D4: WWW COSTCO COM -> 온라인쇼핑 / Costco 온라인
A5: 보험 | B5: Amazon | D5: Amazon -> 온라인쇼핑 / Amazon
A6: 엔터테인먼트 | B6: 자동차보험 | D6: Progressive Insurance -> 보험 / 자동차보험
A7: 결제/이체 | B7: 게임/디지털 | D7: Nintendo -> 엔터테인먼트 / 게임/디지털
A8: 환불/크레딧 | B8: 카드대금 결제 | D8: 결제 및 환불은 지출 합계와 별도로 집계
A9: 기타/확인필요 | B9: 환불/반품
B10: 기타

Sheet 전체거래
A1: 2026년 전체 카드 거래 - 실제 사용일 기준
A3: 구매 지출 합계 | B3: =SUM(L11:L86) | D3: 편집 안내 | E3: 사용자_대분류/사용자_세부분류/사용자_메모 열은 직접 수정용입니다. 원본 분류는 비교를 위해 보존했습니다.
A4: 환불/크레딧 합계 | B4: =SUM(M11:M86)
A5: 카드대금 결제 합계 | B5: =SUM(N11:N86)
A6: 순액 | B6: =SUM(O11:O86)
A7: 거래 수 | B7: 76
A10: ID | B10: 사용일 | C10: 전기일 | D10: 카드 | E10: 거래유형 | F10: 상점/원본설명 | G10: 표준상점 | H10: 원본_대분류 | I10: 원본_세부분류 | J10: 상세태그 | K10: 원본금액 | L10: 지출금액 | M10: 환불/크레딧 | N10: 결제금액 | O10: 순액 | P10: 명세서월 | Q10: 원본파일 | R10: 사용자_대분류 | S10: 사용자_세부분류 | T10: 사용자_메모 | U10: 검토필요
A11: 20260101-0001 | B11: 46023 | D11: Costco Anywhere Visa (Citi) ****6858 | E11: 결제 | F11: AUTOPAY 240208110646284RAUTOPAY AUTO-PMT | G11: Card Payment | H11: 결제/이체 | I11: 카드대금 결제 | J11: 카드결제 | K11: -130.92 | L11: =IF($E11="구매",$K11,0) | M11: =IF($E11="환불/크레딧",$K11,0) | N11: =IF($E11="결제",$K11,0) | O11: =$K11 | P11: 2026-01 | Q11: January2026_f0b0.pdf
A12: 20260101-0002 | B12: 46023 | D12: Costco Anywhere Visa (Citi) ****6858 | E12: 결제 | F12: ONLINE PAYMENT, THANK YOU | G12: Card Payment | H12: 결제/이체 | I12: 카드대금 결제 | J12: 카드결제 | K12: -275.23 | L12: =IF($E12="구매",$K12,0) | M12: =IF($E12="환불/크레딧",$K12,0) | N12: =IF($E12="결제",$K12,0) | O12: =$K12 | P12: 2026-01 | Q12: January2026_f0b0.pdf
A13: 20260105-0003 | B13: 46027 | C13: 46028 | D13: Costco Anywhere Visa (Citi) ****6858 | E13: 구매 | F13: COSTCO WHSE #0484 OREM UT | G13: Costco Warehouse | H13: 식료품/생활용품 | I13: Costco 매장 | J13: Costco 매장 | K13: 122.94 | L13: =IF($E13="구매",$K13,0) | M13: =IF($E13="환불/크레딧",$K13,0) | N13: =IF($E13="결제",$K13,0) | O13: =$K13 | P13: 2026-01 | Q13: January2026_f0b0.pdf
A14: 20260108-0004 | B14: 46030 | C14: 46030 | D14: Costco Anywhere Visa (Citi) ****6858 | E14: 구매 | F14: WWW COSTCO COM 800-955-2292 WA | G14: Costco Online | H14: 온라인쇼핑 | I14: Costco 온라인 | J14: Costco 온라인 | K14: 32.21 | L14: =IF($E14="구매",$K14,0) | M14: =IF($E14="환불/크레딧",$K14,0) | N14: =IF($E14="결제",$K14,0) | O14: =$K14 | P14: 2026-02 | Q14: February2026_f8d6.pdf
A15: 20260108-0005 | B15: 46030 | C15: 46030 | D15: Costco Anywhere Visa (Citi) ****6858 | E15: 구매 | F15: WWW COSTCO COM 800-955-2292 WA | G15: Costco Online | H15: 온라인쇼핑 | I15: Costco 온라인 | J15: Costco 온라인 | K15: 32.21 | L15: =IF($E15="구매",$K15,0) | M15: =IF($E15="환불/크레딧",$K15,0) | N15: =IF($E15="결제",$K15,0) | O15: =$K15 | P15: 2026-02 | Q15: February2026_f8d6.pdf
A16: 20260112-0006 | B16: 46034 | C16: 46034 | D16: Costco Anywhere Visa (Citi) ****6858 | E16: 구매 | F16: COSTCO GAS #0484 OREM UT | G16: Costco Gas | H16: 교통/주유 | I16: 주유 | J16: Costco Gas | K16: 29.57 | L16: =IF($E16="구매",$K16,0) | M16: =IF($E16="환불/크레딧",$K16,0) | N16: =IF($E16="결제",$K16,0) | O16: =$K16 | P16: 2026-02 | Q16: February2026_f8d6.pdf
A17: 20260112-0007 | B17: 46034 | C17: 46034 | D17: Costco Anywhere Visa (Citi) ****6858 | E17: 구매 | F17: COSTCO WHSE #0484 OREM UT | G17: Costco Warehouse | H17: 식료품/생활용품 | I17: Costco 매장 | J17: Costco 매장 | K17: 16.25 | L17: =IF($E17="구매",$K17,0) | M17: =IF($E17="환불/크레딧",$K17,0) | N17: =IF($E17="결제",$K17,0) | O17: =$K17 | P17: 2026-02 | Q17: February2026_f8d6.pdf
A18: 20260124-0008 | B18: 46046 | C18: 46046 | D18: Costco Anywhere Visa (Citi) ****6858 | E18: 구매 | F18: COSTCO WHSE #0484 OREM UT | G18: Costco Warehouse | H18: 식료품/생활용품 | I18: Costco 매장 | J18: Costco 매장 | K18: 60.11 | L18: =IF($E18="구매",$K18,0) | M18: =IF($E18="환불/크레딧",$K18,0) | N18: =IF($E18="결제",$K18,0) | O18: =$K18 | P18: 2026-02 | Q18: February2026_f8d6.pdf
A19: 20260127-0009 | B19: 46049 | D19: Costco Anywhere Visa (Citi) ****6858 | E19: 결제 | F19: ONLINE PAYMENT, THANK YOU | G19: Card Payment | H19: 결제/이체 | I19: 카드대금 결제 | J19: 카드결제 | K19: -162.37 | L19: =IF($E19="구매",$K19,0) | M19: =IF($E19="환불/크레딧",$K19,0) | N19: =IF($E19="결제",$K19,0) | O19: =$K19 | P19: 2026-02 | Q19: February2026_f8d6.pdf
A20: 20260130-0010 | B20: 46052 | C20: 46052 | D20: Costco Anywhere Visa (Citi) ****6858 | E20: 구매 | F20: COSTCO GAS #0484 OREM UT | G20: Costco Gas | H20: 교통/주유 | I20: 주유 | J20: Costco Gas | K20: 33.6 | L20: =IF($E20="구매",$K20,0) | M20: =IF($E20="환불/크레딧",$K20,0) | N20: =IF($E20="결제",$K20,0) | O20: =$K20 | P20: 2026-02 | Q20: February2026_f8d6.pdf
A21: 20260210-0011 | B21: 46063 | C21: 46063 | D21: Costco Anywhere Visa (Citi) ****6858 | E21: 구매 | F21: COSTCO WHSE #0484 OREM UT | G21: Costco Warehouse | H21: 식료품/생활용품 | I21: Costco 매장 | J21: Costco 매장 | K21: 62.16 | L21: =IF($E21="구매",$K21,0) | M21: =IF($E21="환불/크레딧",$K21,0) | N21: =IF($E21="결제",$K21,0) | O21: =$K21 | P21: 2026-03 | Q21: March2026_da89.pdf
A22: 20260211-0012 | B22: 46064 | D22: Prime Visa (Chase) ****6217 | E22: 구매 | F22: AMAZON MKTPL*FL11A1493 Amzn.com/bill WA | G22: Amazon | H22: 온라인쇼핑 | I22: Amazon | J22: Amazon | K22: 0.53 | L22: =IF($E22="구매",$K22,0) | M22: =IF($E22="환불/크레딧",$K22,0) | N22: =IF($E22="결제",$K22,0) | O22: =$K22 | P22: 2026-02 | Q22: B3CDA793-1958-4FE0-A464-444F7501BD7F-list_3284.pdf
A23: 20260219-0013 | B23: 46072 | C23: 46072 | D23: Costco Anywhere Visa (Citi) ****6858 | E23: 구매 | F23: COSTCO GAS #0484 OREM UT | G23: Costco Gas | H23: 교통/주유 | I23: 주유 | J23: Costco Gas | K23: 27.06 | L23: =IF($E23="구매",$K23,0) | M23: =IF($E23="환불/크레딧",$K23,0) | N23: =IF($E23="결제",$K23,0) | O23: =$K23 | P23: 2026-03 | Q23: March2026_da89.pdf
A24: 20260219-0014 | B24: 46072 | C24: 46072 | D24: Costco Anywhere Visa (Citi) ****6858 | E24: 구매 | F24: COSTCO WHSE #0484 OREM UT | G24: Costco Warehouse | H24: 식료품/생활용품 | I24: Costco 매장 | J24: Costco 매장 | K24: 257.87 | L24: =IF($E24="구매",$K24,0) | M24: =IF($E24="환불/크레딧",$K24,0) | N24: =IF($E24="결제",$K24,0) | O24: =$K24 | P24: 2026-03 | Q24: March2026_da89.pdf
A25: 20260224-0015 | B25: 46077 | C25: 46077 | D25: Costco Anywhere Visa (Citi) ****6858 | E25: 구매 | F25: COSTCO WHSE #0484 OREM UT | G25: Costco Warehouse | H25: 식료품/생활용품 | I25: Costco 매장 | J25: Costco 매장 | K25: 12.88 | L25: =IF($E25="구매",$K25,0) | M25: =IF($E25="환불/크레딧",$K25,0) | N25: =IF($E25="결제",$K25,0) | O25: =$K25 | P25: 2026-03 | Q25: March2026_da89.pdf
A26: 20260224-0016 | B26: 46077 | D26: Costco Anywhere Visa (Citi) ****6858 | E26: 결제 | F26: ONLINE PAYMENT, THANK YOU | G26: Card Payment | H26: 결제/이체 | I26: 카드대금 결제 | J26: 카드결제 | K26: -380.69 | L26: =IF($E26="구매",$K26,0) | M26: =IF($E26="환불/크레딧",$K26,0) | N26: =IF($E26="결제",$K26,0) | O26: =$K26 | P26: 2026-03 | Q26: March2026_da89.pdf
A27: 20260227-0017 | B27: 46080 | C27: 46080 | D27: Costco Anywhere Visa (Citi) ****6858 | E27: 구매 | F27: COSTCO WHSE #0484 OREM UT | G27: Costco Warehouse | H27: 식료품/생활용품 | I27: Costco 매장 | J27: Costco 매장 | K27: 193.4 | L27: =IF($E27="구매",$K27,0) | M27: =IF($E27="환불/크레딧",$K27,0) | N27: =IF($E27="결제",$K27,0) | O27: =$K27 | P27: 2026-03 | Q27: March2026_da89.pdf
A28: 20260228-0018 | B28: 46081 | D28: Costco Anywhere Visa (Citi) ****6858 | E28: 환불/크레딧 | F28: WWW COSTCO COM 800-955-2292 WA | G28: Costco | H28: 환불/크레딧 | I28: 환불/반품 | J28: Costco 환불 | K28: -32.21 | L28: =IF($E28="구매",$K28,0) | M28: =IF($E28="환불/크레딧",$K28,0) | N28: =IF($E28="결제",$K28,0) | O28: =$K28 | P28: 2026-03 | Q28: March2026_da89.pdf
A29: 20260303-0019 | B29: 46084 | D29: Prime Visa (Chase) ****6217 | E29: 구매 | F29: AMAZON MKTPL*B99426SF0 Amzn.com/bill WA | G29: Amazon | H29: 온라인쇼핑 | I29: Amazon | J29: Amazon | K29: 37.6 | L29: =IF($E29="구매",$K29,0) | M29: =IF($E29="환불/크레딧",$K29,0) | N29: =IF($E29="결제",$K29,0) | O29: =$K29 | P29: 2026-03 | Q29: 36C0F7B9-D67A-4AE6-9684-B5F848CBA9D5-list_4699.pdf
A30: 20260316-0020 | B30: 46097 | D30: Costco Anywhere Visa (Citi) ****6858 | E30: 결제 | F30: ONLINE PAYMENT, THANK YOU | G30: Card Payment | H30: 결제/이체 | I30: 카드대금 결제 | J30: 카드결제 | K30: -174.07 | L30: =IF($E30="구매",$K30,0) | M30: =IF($E30="환불/크레딧",$K30,0) | N30: =IF($E30="결제",$K30,0) | O30: =$K30 | P30: 2026-04 | Q30: April2026_4952.pdf
A31: 20260317-0021 | B31: 46098 | C31: 46098 | D31: Costco Anywhere Visa (Citi) ****6858 | E31: 구매 | F31: COSTCO GAS #0484 OREM UT | G31: Costco Gas | H31: 교통/주유 | I31: 주유 | J31: Costco Gas | K31: 44.1 | L31: =IF($E31="구매",$K31,0) | M31: =IF($E31="환불/크레딧",$K31,0) | N31: =IF($E31="결제",$K31,0) | O31: =$K31 | P31: 2026-04 | Q31: April2026_4952.pdf
A32: 20260317-0022 | B32: 46098 | C32: 46098 | D32: Costco Anywhere Visa (Citi) ****6858 | E32: 구매 | F32: COSTCO WHSE #0484 OREM UT | G32: Costco Warehouse | H32: 식료품/생활용품 | I32: Costco 매장 | J32: Costco 매장 | K32: 108.48 | L32: =IF($E32="구매",$K32,0) | M32: =IF($E32="환불/크레딧",$K32,0) | N32: =IF($E32="결제",$K32,0) | O32: =$K32 | P32: 2026-04 | Q32: April2026_4952.pdf
A33: 20260325-0023 | B33: 46106 | D33: Costco Anywhere Visa (Citi) ****6858 | E33: 결제 | F33: ONLINE PAYMENT, THANK YOU | G33: Card Payment | H33: 결제/이체 | I33: 카드대금 결제 | J33: 카드결제 | K33: -152.58 | L33: =IF($E33="구매",$K33,0) | M33: =IF($E33="환불/크레딧",$K33,0) | N33: =IF($E33="결제",$K33,0) | O33: =$K33 | P33: 2026-04 | Q33: April2026_4952.pdf
A34: 20260330-0024 | B34: 46111 | C34: 46111 | D34: Costco Anywhere Visa (Citi) ****6858 | E34: 구매 | F34: COSTCO WHSE #0484 OREM UT | G34: Costco Warehouse | H34: 식료품/생활용품 | I34: Costco 매장 | J34: Costco 매장 | K34: 111.46 | L34: =IF($E34="구매",$K34,0) | M34: =IF($E34="환불/크레딧",$K34,0) | N34: =IF($E34="결제",$K34,0) | O34: =$K34 | P34: 2026-04 | Q34: April2026_4952.pdf
A35: 20260403-0025 | B35: 46115 | C35: 46115 | D35: Costco Anywhere Visa (Citi) ****6858 | E35: 구매 | F35: COSTCO GAS #0484 OREM UT | G35: Costco Gas | H35: 교통/주유 | I35: 주유 | J35: Costco Gas | K35: 41.47 | L35: =IF($E35="구매",$K35,0) | M35: =IF($E35="환불/크레딧",$K35,0) | N35: =IF($E35="결제",$K35,0) | O35: =$K35 | P35: 2026-04 | Q35: April2026_4952.pdf
A36: 20260403-0026 | B36: 46115 | C36: 46115 | D36: Costco Anywhere Visa (Citi) ****6858 | E36: 구매 | F36: COSTCO WHSE #0484 OREM UT | G36: Costco Warehouse | H36: 식료품/생활용품 | I36: Costco 매장 | J36: Costco 매장 | K36: 33.81 | L36: =IF($E36="구매",$K36,0) | M36: =IF($E36="환불/크레딧",$K36,0) | N36: =IF($E36="결제",$K36,0) | O36: =$K36 | P36: 2026-04 | Q36: April2026_4952.pdf
A37: 20260403-0027 | B37: 46115 | D37: Costco Anywhere Visa (Citi) ****6858 | E37: 결제 | F37: ONLINE PAYMENT, THANK YOU | G37: Card Payment | H37: 결제/이체 | I37: 카드대금 결제 | J37: 카드결제 | K37: -111.46 | L37: =IF($E37="구매",$K37,0) | M37: =IF($E37="환불/크레딧",$K37,0) | N37: =IF($E37="결제",$K37,0) | O37: =$K37 | P37: 2026-04 | Q37: April2026_4952.pdf
A38: 20260403-0028 | B38: 46115 | D38: Prime Visa (Chase) ****6217 | E38: 구매 | F38: AMAZON MKTPL*B71L99J32 Amzn.com/bill WA | G38: Amazon | H38: 온라인쇼핑 | I38: Amazon | J38: Amazon | K38: 10.73 | L38: =IF($E38="구매",$K38,0) | M38: =IF($E38="환불/크레딧",$K38,0) | N38: =IF($E38="결제",$K38,0) | O38: =$K38 | P38: 2026-04 | Q38: BE3F4263-FAF2-4A9C-87A5-53852C30604D-list_09af.pdf
A39: 20260403-0029 | B39: 46115 | D39: Prime Visa (Chase) ****6217 | E39: 구매 | F39: Amazon.com*BG2082560 Amzn.com/bill WA | G39: Amazon | H39: 온라인쇼핑 | I39: Amazon | J39: Amazon | K39: 5.63 | L39: =IF($E39="구매",$K39,0) | M39: =IF($E39="환불/크레딧",$K39,0) | N39: =IF($E39="결제",$K39,0) | O39: =$K39 | P39: 2026-04 | Q39: BE3F4263-FAF2-4A9C-87A5-53852C30604D-list_09af.pdf
A40: 20260406-0030 | B40: 46118 | D40: Prime Visa (Chase) ****6217 | E40: 구매 | F40: AMAZON MKTPL*BC0SR41L1 Amzn.com/bill WA | G40: Amazon | H40: 온라인쇼핑 | I40: Amazon | J40: Amazon | K40: 16.98 | L40: =IF($E40="구매",$K40,0) | M40: =IF($E40="환불/크레딧",$K40,0) | N40: =IF($E40="결제",$K40,0) | O40: =$K40 | P40: 2026-04 | Q40: BE3F4263-FAF2-4A9C-87A5-53852C30604D-list_09af.pdf
A41: 20260407-0031 | B41: 46119 | C41: 46119 | D41: Costco Anywhere Visa (Citi) ****6858 | E41: 구매 | F41: WWW COSTCO COM 800-955-2292 WA | G41: Costco Online | H41: 온라인쇼핑 | I41: Costco 온라인 | J41: Costco 온라인 | K41: 42.97 | L41: =IF($E41="구매",$K41,0) | M41: =IF($E41="환불/크레딧",$K41,0) | N41: =IF($E41="결제",$K41,0) | O41: =$K41 | P41: 2026-05 | Q41: May2026_2c5d.pdf
A42: 20260407-0032 | B42: 46119 | D42: Prime Visa (Chase) ****6217 | E42: 구매 | F42: AMAZON MKTPL*BC3EP1N30 Amzn.com/bill WA | G42: Amazon | H42: 온라인쇼핑 | I42: Amazon | J42: Amazon | K42: 11.13 | L42: =IF($E42="구매",$K42,0) | M42: =IF($E42="환불/크레딧",$K42,0) | N42: =IF($E42="결제",$K42,0) | O42: =$K42 | P42: 2026-04 | Q42: BE3F4263-FAF2-4A9C-87A5-53852C30604D-list_09af.pdf
A43: 20260407-0033 | B43: 46119 | D43: Prime Visa (Chase) ****6217 | E43: 구매 | F43: Amazon.com*BC0EP2NY0 Amzn.com/bill WA | G43: Amazon | H43: 온라인쇼핑 | I43: Amazon | J43: Amazon | K43: 13.2 | L43: =IF($E43="구매",$K43,0) | M43: =IF($E43="환불/크레딧",$K43,0) | N43: =IF($E43="결제",$K43,0) | O43: =$K43 | P43: 2026-04 | Q43: BE3F4263-FAF2-4A9C-87A5-53852C30604D-list_09af.pdf
...

Sheet 01월
A1: 2026년 1월 카드 사용내역
A3: 구매 지출 합계 | B3: =SUM(L11:L20) | D3: 편집 안내 | E3: 사용자_대분류/사용자_세부분류/사용자_메모 열은 직접 수정용입니다. 원본 분류는 비교를 위해 보존했습니다.
A4: 환불/크레딧 합계 | B4: =SUM(M11:M20)
A5: 카드대금 결제 합계 | B5: =SUM(N11:N20)
A6: 순액 | B6: =SUM(O11:O20)
A7: 거래 수 | B7: 10
A10: ID | B10: 사용일 | C10: 전기일 | D10: 카드 | E10: 거래유형 | F10: 상점/원본설명 | G10: 표준상점 | H10: 원본_대분류 | I10: 원본_세부분류 | J10: 상세태그 | K10: 원본금액 | L10: 지출금액 | M10: 환불/크레딧 | N10: 결제금액 | O10: 순액 | P10: 명세서월 | Q10: 원본파일 | R10: 사용자_대분류 | S10: 사용자_세부분류 | T10: 사용자_메모 | U10: 검토필요
A11: 20260101-0001 | B11: 46023 | D11: Costco Anywhere Visa (Citi) ****6858 | E11: 결제 | F11: AUTOPAY 240208110646284RAUTOPAY AUTO-PMT | G11: Card Payment | H11: 결제/이체 | I11: 카드대금 결제 | J11: 카드결제 | K11: -130.92 | L11: =IF($E11="구매",$K11,0) | M11: =IF($E11="환불/크레딧",$K11,0) | N11: =IF($E11="결제",$K11,0) | O11: =$K11 | P11: 2026-01 | Q11: January2026_f0b0.pdf
A12: 20260101-0002 | B12: 46023 | D12: Costco Anywhere Visa (Citi) ****6858 | E12: 결제 | F12: ONLINE PAYMENT, THANK YOU | G12: Card Payment | H12: 결제/이체 | I12: 카드대금 결제 | J12: 카드결제 | K12: -275.23 | L12: =IF($E12="구매",$K12,0) | M12: =IF($E12="환불/크레딧",$K12,0) | N12: =IF($E12="결제",$K12,0) | O12: =$K12 | P12: 2026-01 | Q12: January2026_f0b0.pdf
A13: 20260105-0003 | B13: 46027 | C13: 46028 | D13: Costco Anywhere Visa (Citi) ****6858 | E13: 구매 | F13: COSTCO WHSE #0484 OREM UT | G13: Costco Warehouse | H13: 식료품/생활용품 | I13: Costco 매장 | J13: Costco 매장 | K13: 122.94 | L13: =IF($E13="구매",$K13,0) | M13: =IF($E13="환불/크레딧",$K13,0) | N13: =IF($E13="결제",$K13,0) | O13: =$K13 | P13: 2026-01 | Q13: January2026_f0b0.pdf
A14: 20260108-0004 | B14: 46030 | C14: 46030 | D14: Costco Anywhere Visa (Citi) ****6858 | E14: 구매 | F14: WWW COSTCO COM 800-955-2292 WA | G14: Costco Online | H14: 온라인쇼핑 | I14: Costco 온라인 | J14: Costco 온라인 | K14: 32.21 | L14: =IF($E14="구매",$K14,0) | M14: =IF($E14="환불/크레딧",$K14,0) | N14: =IF($E14="결제",$K14,0) | O14: =$K14 | P14: 2026-02 | Q14: February2026_f8d6.pdf
A15: 20260108-0005 | B15: 46030 | C15: 46030 | D15: Costco Anywhere Visa (Citi) ****6858 | E15: 구매 | F15: WWW COSTCO COM 800-955-2292 WA | G15: Costco Online | H15: 온라인쇼핑 | I15: Costco 온라인 | J15: Costco 온라인 | K15: 32.21 | L15: =IF($E15="구매",$K15,0) | M15: =IF($E15="환불/크레딧",$K15,0) | N15: =IF($E15="결제",$K15,0) | O15: =$K15 | P15: 2026-02 | Q15: February2026_f8d6.pdf
A16: 20260112-0006 | B16: 46034 | C16: 46034 | D16: Costco Anywhere Visa (Citi) ****6858 | E16: 구매 | F16: COSTCO GAS #0484 OREM UT | G16: Costco Gas | H16: 교통/주유 | I16: 주유 | J16: Costco Gas | K16: 29.57 | L16: =IF($E16="구매",$K16,0) | M16: =IF($E16="환불/크레딧",$K16,0) | N16: =IF($E16="결제",$K16,0) | O16: =$K16 | P16: 2026-02 | Q16: February2026_f8d6.pdf
A17: 20260112-0007 | B17: 46034 | C17: 46034 | D17: Costco Anywhere Visa (Citi) ****6858 | E17: 구매 | F17: COSTCO WHSE #0484 OREM UT | G17: Costco Warehouse | H17: 식료품/생활용품 | I17: Costco 매장 | J17: Costco 매장 | K17: 16.25 | L17: =IF($E17="구매",$K17,0) | M17: =IF($E17="환불/크레딧",$K17,0) | N17: =IF($E17="결제",$K17,0) | O17: =$K17 | P17: 2026-02 | Q17: February2026_f8d6.pdf
A18: 20260124-0008 | B18: 46046 | C18: 46046 | D18: Costco Anywhere Visa (Citi) ****6858 | E18: 구매 | F18: COSTCO WHSE #0484 OREM UT | G18: Costco Warehouse | H18: 식료품/생활용품 | I18: Costco 매장 | J18: Costco 매장 | K18: 60.11 | L18: =IF($E18="구매",$K18,0) | M18: =IF($E18="환불/크레딧",$K18,0) | N18: =IF($E18="결제",$K18,0) | O18: =$K18 | P18: 2026-02 | Q18: February2026_f8d6.pdf
A19: 20260127-0009 | B19: 46049 | D19: Costco Anywhere Visa (Citi) ****6858 | E19: 결제 | F19: ONLINE PAYMENT, THANK YOU | G19: Card Payment | H19: 결제/이체 | I19: 카드대금 결제 | J19: 카드결제 | K19: -162.37 | L19: =IF($E19="구매",$K19,0) | M19: =IF($E19="환불/크레딧",$K19,0) | N19: =IF($E19="결제",$K19,0) | O19: =$K19 | P19: 2026-02 | Q19: February2026_f8d6.pdf
A20: 20260130-0010 | B20: 46052 | C20: 46052 | D20: Costco Anywhere Visa (Citi) ****6858 | E20: 구매 | F20: COSTCO GAS #0484 OREM UT | G20: Costco Gas | H20: 교통/주유 | I20: 주유 | J20: Costco Gas | K20: 33.6 | L20: =IF($E20="구매",$K20,0) | M20: =IF($E20="환불/크레딧",$K20,0) | N20: =IF($E20="결제",$K20,0) | O20: =$K20 | P20: 2026-02 | Q20: February2026_f8d6.pdf

Sheet 02월
A1: 2026년 2월 카드 사용내역
A3: 구매 지출 합계 | B3: =SUM(L11:L18) | D3: 편집 안내 | E3: 사용자_대분류/사용자_세부분류/사용자_메모 열은 직접 수정용입니다. 원본 분류는 비교를 위해 보존했습니다.
A4: 환불/크레딧 합계 | B4: =SUM(M11:M18)
A5: 카드대금 결제 합계 | B5: =SUM(N11:N18)
A6: 순액 | B6: =SUM(O11:O18)
A7: 거래 수 | B7: 8
A10: ID | B10: 사용일 | C10: 전기일 | D10: 카드 | E10: 거래유형 | F10: 상점/원본설명 | G10: 표준상점 | H10: 원본_대분류 | I10: 원본_세부분류 | J10: 상세태그 | K10: 원본금액 | L10: 지출금액 | M10: 환불/크레딧 | N10: 결제금액 | O10: 순액 | P10: 명세서월 | Q10: 원본파일 | R10: 사용자_대분류 | S10: 사용자_세부분류 | T10: 사용자_메모 | U10: 검토필요
A11: 20260210-0001 | B11: 46063 | C11: 46063 | D11: Costco Anywhere Visa (Citi) ****6858 | E11: 구매 | F11: COSTCO WHSE #0484 OREM UT | G11: Costco Warehouse | H11: 식료품/생활용품 | I11: Costco 매장 | J11: Costco 매장 | K11: 62.16 | L11: =IF($E11="구매",$K11,0) | M11: =IF($E11="환불/크레딧",$K11,0) | N11: =IF($E11="결제",$K11,0) | O11: =$K11 | P11: 2026-03 | Q11: March2026_da89.pdf
A12: 20260211-0002 | B12: 46064 | D12: Prime Visa (Chase) ****6217 | E12: 구매 | F12: AMAZON MKTPL*FL11A1493 Amzn.com/bill WA | G12: Amazon | H12: 온라인쇼핑 | I12: Amazon | J12: Amazon | K12: 0.53 | L12: =IF($E12="구매",$K12,0) | M12: =IF($E12="환불/크레딧",$K12,0) | N12: =IF($E12="결제",$K12,0) | O12: =$K12 | P12: 2026-02 | Q12: B3CDA793-1958-4FE0-A464-444F7501BD7F-list_3284.pdf
A13: 20260219-0003 | B13: 46072 | C13: 46072 | D13: Costco Anywhere Visa (Citi) ****6858 | E13: 구매 | F13: COSTCO GAS #0484 OREM UT | G13: Costco Gas | H13: 교통/주유 | I13: 주유 | J13: Costco Gas | K13: 27.06 | L13: =IF($E13="구매",$K13,0) | M13: =IF($E13="환불/크레딧",$K13,0) | N13: =IF($E13="결제",$K13,0) | O13: =$K13 | P13: 2026-03 | Q13: March2026_da89.pdf
A14: 20260219-0004 | B14: 46072 | C14: 46072 | D14: Costco Anywhere Visa (Citi) ****6858 | E14: 구매 | F14: COSTCO WHSE #0484 OREM UT | G14: Costco Warehouse | H14: 식료품/생활용품 | I14: Costco 매장 | J14: Costco 매장 | K14: 257.87 | L14: =IF($E14="구매",$K14,0) | M14: =IF($E14="환불/크레딧",$K14,0) | N14: =IF($E14="결제",$K14,0) | O14: =$K14 | P14: 2026-03 | Q14: March2026_da89.pdf
A15: 20260224-0005 | B15: 46077 | C15: 46077 | D15: Costco Anywhere Visa (Citi) ****6858 | E15: 구매 | F15: COSTCO WHSE #0484 OREM UT | G15: Costco Warehouse | H15: 식료품/생활용품 | I15: Costco 매장 | J15: Costco 매장 | K15: 12.88 | L15: =IF($E15="구매",$K15,0) | M15: =IF($E15="환불/크레딧",$K15,0) | N15: =IF($E15="결제",$K15,0) | O15: =$K15 | P15: 2026-03 | Q15: March2026_da89.pdf
A16: 20260224-0006 | B16: 46077 | D16: Costco Anywhere Visa (Citi) ****6858 | E16: 결제 | F16: ONLINE PAYMENT, THANK YOU | G16: Card Payment | H16: 결제/이체 | I16: 카드대금 결제 | J16: 카드결제 | K16: -380.69 | L16: =IF($E16="구매",$K16,0) | M16: =IF($E16="환불/크레딧",$K16,0) | N16: =IF($E16="결제",$K16,0) | O16: =$K16 | P16: 2026-03 | Q16: March2026_da89.pdf
A17: 20260227-0007 | B17: 46080 | C17: 46080 | D17: Costco Anywhere Visa (Citi) ****6858 | E17: 구매 | F17: COSTCO WHSE #0484 OREM UT | G17: Costco Warehouse | H17: 식료품/생활용품 | I17: Costco 매장 | J17: Costco 매장 | K17: 193.4 | L17: =IF($E17="구매",$K17,0) | M17: =IF($E17="환불/크레딧",$K17,0) | N17: =IF($E17="결제",$K17,0) | O17: =$K17 | P17: 2026-03 | Q17: March2026_da89.pdf
A18: 20260228-0008 | B18: 46081 | D18: Costco Anywhere Visa (Citi) ****6858 | E18: 환불/크레딧 | F18: WWW COSTCO COM 800-955-2292 WA | G18: Costco | H18: 환불/크레딧 | I18: 환불/반품 | J18: Costco 환불 | K18: -32.21 | L18: =IF($E18="구매",$K18,0) | M18: =IF($E18="환불/크레딧",$K18,0) | N18: =IF($E18="결제",$K18,0) | O18: =$K18 | P18: 2026-03 | Q18: March2026_da89.pdf

Sheet 03월
A1: 2026년 3월 카드 사용내역
A3: 구매 지출 합계 | B3: =SUM(L11:L16) | D3: 편집 안내 | E3: 사용자_대분류/사용자_세부분류/사용자_메모 열은 직접 수정용입니다. 원본 분류는 비교를 위해 보존했습니다.
A4: 환불/크레딧 합계 | B4: =SUM(M11:M16)
A5: 카드대금 결제 합계 | B5: =SUM(N11:N16)
A6: 순액 | B6: =SUM(O11:O16)
A7: 거래 수 | B7: 6
A10: ID | B10: 사용일 | C10: 전기일 | D10: 카드 | E10: 거래유형 | F10: 상점/원본설명 | G10: 표준상점 | H10: 원본_대분류 | I10: 원본_세부분류 | J10: 상세태그 | K10: 원본금액 | L10: 지출금액 | M10: 환불/크레딧 | N10: 결제금액 | O10: 순액 | P10: 명세서월 | Q10: 원본파일 | R10: 사용자_대분류 | S10: 사용자_세부분류 | T10: 사용자_메모 | U10: 검토필요
A11: 20260303-0001 | B11: 46084 | D11: Prime Visa (Chase) ****6217 | E11: 구매 | F11: AMAZON MKTPL*B99426SF0 Amzn.com/bill WA | G11: Amazon | H11: 온라인쇼핑 | I11: Amazon | J11: Amazon | K11: 37.6 | L11: =IF($E11="구매",$K11,0) | M11: =IF($E11="환불/크레딧",$K11,0) | N11: =IF($E11="결제",$K11,0) | O11: =$K11 | P11: 2026-03 | Q11: 36C0F7B9-D67A-4AE6-9684-B5F848CBA9D5-list_4699.pdf
A12: 20260316-0002 | B12: 46097 | D12: Costco Anywhere Visa (Citi) ****6858 | E12: 결제 | F12: ONLINE PAYMENT, THANK YOU | G12: Card Payment | H12: 결제/이체 | I12: 카드대금 결제 | J12: 카드결제 | K12: -174.07 | L12: =IF($E12="구매",$K12,0) | M12: =IF($E12="환불/크레딧",$K12,0) | N12: =IF($E12="결제",$K12,0) | O12: =$K12 | P12: 2026-04 | Q12: April2026_4952.pdf
A13: 20260317-0003 | B13: 46098 | C13: 46098 | D13: Costco Anywhere Visa (Citi) ****6858 | E13: 구매 | F13: COSTCO GAS #0484 OREM UT | G13: Costco Gas | H13: 교통/주유 | I13: 주유 | J13: Costco Gas | K13: 44.1 | L13: =IF($E13="구매",$K13,0) | M13: =IF($E13="환불/크레딧",$K13,0) | N13: =IF($E13="결제",$K13,0) | O13: =$K13 | P13: 2026-04 | Q13: April2026_4952.pdf
A14: 20260317-0004 | B14: 46098 | C14: 46098 | D14: Costco Anywhere Visa (Citi) ****6858 | E14: 구매 | F14: COSTCO WHSE #0484 OREM UT | G14: Costco Warehouse | H14: 식료품/생활용품 | I14: Costco 매장 | J14: Costco 매장 | K14: 108.48 | L14: =IF($E14="구매",$K14,0) | M14: =IF($E14="환불/크레딧",$K14,0) | N14: =IF($E14="결제",$K14,0) | O14: =$K14 | P14: 2026-04 | Q14: April2026_4952.pdf
A15: 20260325-0005 | B15: 46106 | D15: Costco Anywhere Visa (Citi) ****6858 | E15: 결제 | F15: ONLINE PAYMENT, THANK YOU | G15: Card Payment | H15: 결제/이체 | I15: 카드대금 결제 | J15: 카드결제 | K15: -152.58 | L15: =IF($E15="구매",$K15,0) | M15: =IF($E15="환불/크레딧",$K15,0) | N15: =IF($E15="결제",$K15,0) | O15: =$K15 | P15: 2026-04 | Q15: April2026_4952.pdf
A16: 20260330-0006 | B16: 46111 | C16: 46111 | D16: Costco Anywhere Visa (Citi) ****6858 | E16: 구매 | F16: COSTCO WHSE #0484 OREM UT | G16: Costco Warehouse | H16: 식료품/생활용품 | I16: Costco 매장 | J16: Costco 매장 | K16: 111.46 | L16: =IF($E16="구매",$K16,0) | M16: =IF($E16="환불/크레딧",$K16,0) | N16: =IF($E16="결제",$K16,0) | O16: =$K16 | P16: 2026-04 | Q16: April2026_4952.pdf

Sheet 04월
A1: 2026년 4월 카드 사용내역
A3: 구매 지출 합계 | B3: =SUM(L11:L34) | D3: 편집 안내 | E3: 사용자_대분류/사용자_세부분류/사용자_메모 열은 직접 수정용입니다. 원본 분류는 비교를 위해 보존했습니다.
A4: 환불/크레딧 합계 | B4: =SUM(M11:M34)
A5: 카드대금 결제 합계 | B5: =SUM(N11:N34)
A6: 순액 | B6: =SUM(O11:O34)
A7: 거래 수 | B7: 24
A10: ID | B10: 사용일 | C10: 전기일 | D10: 카드 | E10: 거래유형 | F10: 상점/원본설명 | G10: 표준상점 | H10: 원본_대분류 | I10: 원본_세부분류 | J10: 상세태그 | K10: 원본금액 | L10: 지출금액 | M10: 환불/크레딧 | N10: 결제금액 | O10: 순액 | P10: 명세서월 | Q10: 원본파일 | R10: 사용자_대분류 | S10: 사용자_세부분류 | T10: 사용자_메모 | U10: 검토필요
A11: 20260403-0001 | B11: 46115 | C11: 46115 | D11: Costco Anywhere Visa (Citi) ****6858 | E11: 구매 | F11: COSTCO GAS #0484 OREM UT | G11: Costco Gas | H11: 교통/주유 | I11: 주유 | J11: Costco Gas | K11: 41.47 | L11: =IF($E11="구매",$K11,0) | M11: =IF($E11="환불/크레딧",$K11,0) | N11: =IF($E11="결제",$K11,0) | O11: =$K11 | P11: 2026-04 | Q11: April2026_4952.pdf
A12: 20260403-0002 | B12: 46115 | C12: 46115 | D12: Costco Anywhere Visa (Citi) ****6858 | E12: 구매 | F12: COSTCO WHSE #0484 OREM UT | G12: Costco Warehouse | H12: 식료품/생활용품 | I12: Costco 매장 | J12: Costco 매장 | K12: 33.81 | L12: =IF($E12="구매",$K12,0) | M12: =IF($E12="환불/크레딧",$K12,0) | N12: =IF($E12="결제",$K12,0) | O12: =$K12 | P12: 2026-04 | Q12: April2026_4952.pdf
A13: 20260403-0003 | B13: 46115 | D13: Costco Anywhere Visa (Citi) ****6858 | E13: 결제 | F13: ONLINE PAYMENT, THANK YOU | G13: Card Payment | H13: 결제/이체 | I13: 카드대금 결제 | J13: 카드결제 | K13: -111.46 | L13: =IF($E13="구매",$K13,0) | M13: =IF($E13="환불/크레딧",$K13,0) | N13: =IF($E13="결제",$K13,0) | O13: =$K13 | P13: 2026-04 | Q13: April2026_4952.pdf
A14: 20260403-0004 | B14: 46115 | D14: Prime Visa (Chase) ****6217 | E14: 구매 | F14: AMAZON MKTPL*B71L99J32 Amzn.com/bill WA | G14: Amazon | H14: 온라인쇼핑 | I14: Amazon | J14: Amazon | K14: 10.73 | L14: =IF($E14="구매",$K14,0) | M14: =IF($E14="환불/크레딧",$K14,0) | N14: =IF($E14="결제",$K14,0) | O14: =$K14 | P14: 2026-04 | Q14: BE3F4263-FAF2-4A9C-87A5-53852C30604D-list_09af.pdf
A15: 20260403-0005 | B15: 46115 | D15: Prime Visa (Chase) ****6217 | E15: 구매 | F15: Amazon.com*BG2082560 Amzn.com/bill WA | G15: Amazon | H15: 온라인쇼핑 | I15: Amazon | J15: Amazon | K15: 5.63 | L15: =IF($E15="구매",$K15,0) | M15: =IF($E15="환불/크레딧",$K15,0) | N15: =IF($E15="결제",$K15,0) | O15: =$K15 | P15: 2026-04 | Q15: BE3F4263-FAF2-4A9C-87A5-53852C30604D-list_09af.pdf
A16: 20260406-0006 | B16: 46118 | D16: Prime Visa (Chase) ****6217 | E16: 구매 | F16: AMAZON MKTPL*BC0SR41L1 Amzn.com/bill WA | G16: Amazon | H16: 온라인쇼핑 | I16: Amazon | J16: Amazon | K16: 16.98 | L16: =IF($E16="구매",$K16,0) | M16: =IF($E16="환불/크레딧",$K16,0) | N16: =IF($E16="결제",$K16,0) | O16: =$K16 | P16: 2026-04 | Q16: BE3F4263-FAF2-4A9C-87A5-53852C30604D-list_09af.pdf
A17: 20260407-0007 | B17: 46119 | C17: 46119 | D17: Costco Anywhere Visa (Citi) ****6858 | E17: 구매 | F17: WWW COSTCO COM 800-955-2292 WA | G17: Costco Online | H17: 온라인쇼핑 | I17: Costco 온라인 | J17: Costco 온라인 | K17: 42.97 | L17: =IF($E17="구매",$K17,0) | M17: =IF($E17="환불/크레딧",$K17,0) | N17: =IF($E17="결제",$K17,0) | O17: =$K17 | P17: 2026-05 | Q17: May2026_2c5d.pdf
A18: 20260407-0008 | B18: 46119 | D18: Prime Visa (Chase) ****6217 | E18: 구매 | F18: AMAZON MKTPL*BC3EP1N30 Amzn.com/bill WA | G18: Amazon | H18: 온라인쇼핑 | I18: Amazon | J18: Amazon | K18: 11.13 | L18: =IF($E18="구매",$K18,0) | M18: =IF($E18="환불/크레딧",$K18,0) | N18: =IF($E18="결제",$K18,0) | O18: =$K18 | P18: 2026-04 | Q18: BE3F4263-FAF2-4A9C-87A5-53852C30604D-list_09af.pdf
A19: 20260407-0009 | B19: 46119 | D19: Prime Visa (Chase) ****6217 | E19: 구매 | F19: Amazon.com*BC0EP2NY0 Amzn.com/bill WA | G19: Amazon | H19: 온라인쇼핑 | I19: Amazon | J19: Amazon | K19: 13.2 | L19: =IF($E19="구매",$K19,0) | M19: =IF($E19="환불/크레딧",$K19,0) | N19: =IF($E19="결제",$K19,0) | O19: =$K19 | P19: 2026-04 | Q19: BE3F4263-FAF2-4A9C-87A5-53852C30604D-list_09af.pdf
A20: 20260408-0010 | B20: 46120 | D20: Prime Visa (Chase) ****6217 | E20: 구매 | F20: AMAZON MKTPL*BC4YY4QQ1 Amzn.com/bill WA | G20: Amazon | H20: 온라인쇼핑 | I20: Amazon | J20: Amazon | K20: 10.73 | L20: =IF($E20="구매",$K20,0) | M20: =IF($E20="환불/크레딧",$K20,0) | N20: =IF($E20="결제",$K20,0) | O20: =$K20 | P20: 2026-04 | Q20: BE3F4263-FAF2-4A9C-87A5-53852C30604D-list_09af.pdf
A21: 20260411-0011 | B21: 46123 | C21: 46123 | D21: Costco Anywhere Visa (Citi) ****6858 | E21: 구매 | F21: COSTCO WHSE #0484 OREM UT | G21: Costco Warehouse | H21: 식료품/생활용품 | I21: Costco 매장 | J21: Costco 매장 | K21: 7.02 | L21: =IF($E21="구매",$K21,0) | M21: =IF($E21="환불/크레딧",$K21,0) | N21: =IF($E21="결제",$K21,0) | O21: =$K21 | P21: 2026-05 | Q21: May2026_2c5d.pdf
A22: 20260411-0012 | B22: 46123 | C22: 46123 | D22: Costco Anywhere Visa (Citi) ****6858 | E22: 구매 | F22: COSTCO WHSE #0484 OREM UT | G22: Costco Warehouse | H22: 식료품/생활용품 | I22: Costco 매장 | J22: Costco 매장 | K22: 146.69 | L22: =IF($E22="구매",$K22,0) | M22: =IF($E22="환불/크레딧",$K22,0) | N22: =IF($E22="결제",$K22,0) | O22: =$K22 | P22: 2026-05 | Q22: May2026_2c5d.pdf
A23: 20260411-0013 | B23: 46123 | D23: Prime Visa (Chase) ****6217 | E23: 구매 | F23: AMAZON MKTPL*BY3SU8XS2 Amzn.com/bill WA | G23: Amazon | H23: 온라인쇼핑 | I23: Amazon | J23: Amazon | K23: 30.89 | L23: =IF($E23="구매",$K23,0) | M23: =IF($E23="환불/크레딧",$K23,0) | N23: =IF($E23="결제",$K23,0) | O23: =$K23 | P23: 2026-04 | Q23: BE3F4263-FAF2-4A9C-87A5-53852C30604D-list_09af.pdf
A24: 20260413-0014 | B24: 46125 | D24: Prime Visa (Chase) ****6217 | E24: 구매 | F24: AMAZON MKTPL*BY9KG8262 Amzn.com/bill WA | G24: Amazon | H24: 온라인쇼핑 | I24: Amazon | J24: Amazon | K24: 9.19 | L24: =IF($E24="구매",$K24,0) | M24: =IF($E24="환불/크레딧",$K24,0) | N24: =IF($E24="결제",$K24,0) | O24: =$K24 | P24: 2026-04 | Q24: BE3F4263-FAF2-4A9C-87A5-53852C30604D-list_09af.pdf
A25: 20260414-0015 | B25: 46126 | D25: Prime Visa (Chase) ****6217 | E25: 구매 | F25: Amazon.com*B74A77521 Amzn.com/bill WA | G25: Amazon | H25: 온라인쇼핑 | I25: Amazon | J25: Amazon | K25: 11.8 | L25: =IF($E25="구매",$K25,0) | M25: =IF($E25="환불/크레딧",$K25,0) | N25: =IF($E25="결제",$K25,0) | O25: =$K25 | P25: 2026-04 | Q25: BE3F4263-FAF2-4A9C-87A5-53852C30604D-list_09af.pdf
A26: 20260416-0016 | B26: 46128 | C26: 46128 | D26: Costco Anywhere Visa (Citi) ****6858 | E26: 구매 | F26: COSTCO GAS #0484 OREM UT | G26: Costco Gas | H26: 교통/주유 | I26: 주유 | J26: Costco Gas | K26: 55.04 | L26: =IF($E26="구매",$K26,0) | M26: =IF($E26="환불/크레딧",$K26,0) | N26: =IF($E26="결제",$K26,0) | O26: =$K26 | P26: 2026-05 | Q26: May2026_2c5d.pdf
A27: 20260417-0017 | B27: 46129 | D27: Prime Visa (Chase) ****6217 | E27: 환불/크레딧 | F27: AMAZON MKTPLACE PMTS Amzn.com/bill WA | G27: Amazon | H27: 환불/크레딧 | I27: 환불/반품 | J27: Amazon 환불 | K27: -9.19 | L27: =IF($E27="구매",$K27,0) | M27: =IF($E27="환불/크레딧",$K27,0) | N27: =IF($E27="결제",$K27,0) | O27: =$K27 | P27: 2026-04 | Q27: BE3F4263-FAF2-4A9C-87A5-53852C30604D-list_09af.pdf
A28: 20260419-0018 | B28: 46131 | C28: 46131 | D28: Costco Anywhere Visa (Citi) ****6858 | E28: 구매 | F28: COSTCO WHSE #0484 OREM UT | G28: Costco Warehouse | H28: 식료품/생활용품 | I28: Costco 매장 | J28: Costco 매장 | K28: 38.66 | L28: =IF($E28="구매",$K28,0) | M28: =IF($E28="환불/크레딧",$K28,0) | N28: =IF($E28="결제",$K28,0) | O28: =$K28 | P28: 2026-05 | Q28: May2026_2c5d.pdf
A29: 20260422-0019 | B29: 46134 | D29: Costco Anywhere Visa (Citi) ****6858 | E29: 결제 | F29: ONLINE PAYMENT, THANK YOU | G29: Card Payment | H29: 결제/이체 | I29: 카드대금 결제 | J29: 카드결제 | K29: -365.66 | L29: =IF($E29="구매",$K29,0) | M29: =IF($E29="환불/크레딧",$K29,0) | N29: =IF($E29="결제",$K29,0) | O29: =$K29 | P29: 2026-05 | Q29: May2026_2c5d.pdf
A30: 20260422-0020 | B30: 46134 | D30: Prime Visa (Chase) ****6217 | E30: 결제 | F30: Payment Thank You-Mobile | G30: Card Payment | H30: 결제/이체 | I30: 카드대금 결제 | J30: 카드결제 | K30: -120.95 | L30: =IF($E30="구매",$K30,0) | M30: =IF($E30="환불/크레딧",$K30,0) | N30: =IF($E30="결제",$K30,0) | O30: =$K30 | P30: 2026-04 | Q30: BE3F4263-FAF2-4A9C-87A5-53852C30604D-list_09af.pdf
A31: 20260425-0021 | B31: 46137 | D31: Prime Visa (Chase) ****6217 | E31: 구매 | F31: AMAZON MKTPL*BJ8XT25Y2 Amzn.com/bill WA | G31: Amazon | H31: 온라인쇼핑 | I31: Amazon | J31: Amazon | K31: 43.59 | L31: =IF($E31="구매",$K31,0) | M31: =IF($E31="환불/크레딧",$K31,0) | N31: =IF($E31="결제",$K31,0) | O31: =$K31 | P31: 2026-04 | Q31: BE3F4263-FAF2-4A9C-87A5-53852C30604D-list_09af.pdf
A32: 20260426-0022 | B32: 46138 | C32: 46138 | D32: Costco Anywhere Visa (Citi) ****6858 | E32: 구매 | F32: COSTCO GAS #0484 OREM UT | G32: Costco Gas | H32: 교통/주유 | I32: 주유 | J32: Costco Gas | K32: 57.18 | L32: =IF($E32="구매",$K32,0) | M32: =IF($E32="환불/크레딧",$K32,0) | N32: =IF($E32="결제",$K32,0) | O32: =$K32 | P32: 2026-05 | Q32: May2026_2c5d.pdf
A33: 20260427-0023 | B33: 46139 | D33: Prime Visa (Chase) ****6217 | E33: 구매 | F33: AMAZON MKTPL*BS2LG7ZQ0 Amzn.com/bill WA | G33: Amazon | H33: 온라인쇼핑 | I33: Amazon | J33: Amazon | K33: 40.82 | L33: =IF($E33="구매",$K33,0) | M33: =IF($E33="환불/크레딧",$K33,0) | N33: =IF($E33="결제",$K33,0) | O33: =$K33 | P33: 2026-04 | Q33: BE3F4263-FAF2-4A9C-87A5-53852C30604D-list_09af.pdf
A34: 20260429-0024 | B34: 46141 | D34: Prime Visa (Chase) ****6217 | E34: 구매 | F34: AMAZON MKTPL*BJ35W1NP1 Amzn.com/bill WA | G34: Amazon | H34: 온라인쇼핑 | I34: Amazon | J34: Amazon | K34: 16.17 | L34: =IF($E34="구매",$K34,0) | M34: =IF($E34="환불/크레딧",$K34,0) | N34: =IF($E34="결제",$K34,0) | O34: =$K34 | P34: 2026-05 | Q34: 69212C10-1B95-4A05-9104-379BBA52768F-list_d242.pdf

Sheet 05월
A1: 2026년 5월 카드 사용내역
A3: 구매 지출 합계 | B3: =SUM(L11:L38) | D3: 편집 안내 | E3: 사용자_대분류/사용자_세부분류/사용자_메모 열은 직접 수정용입니다. 원본 분류는 비교를 위해 보존했습니다.
A4: 환불/크레딧 합계 | B4: =SUM(M11:M38)
A5: 카드대금 결제 합계 | B5: =SUM(N11:N38)
A6: 순액 | B6: =SUM(O11:O38)
A7: 거래 수 | B7: 28
A10: ID | B10: 사용일 | C10: 전기일 | D10: 카드 | E10: 거래유형 | F10: 상점/원본설명 | G10: 표준상점 | H10: 원본_대분류 | I10: 원본_세부분류 | J10: 상세태그 | K10: 원본금액 | L10: 지출금액 | M10: 환불/크레딧 | N10: 결제금액 | O10: 순액 | P10: 명세서월 | Q10: 원본파일 | R10: 사용자_대분류 | S10: 사용자_세부분류 | T10: 사용자_메모 | U10: 검토필요
A11: 20260501-0001 | B11: 46143 | C11: 46143 | D11: Costco Anywhere Visa (Citi) ****6858 | E11: 구매 | F11: COSTCO WHSE #0484 OREM UT | G11: Costco Warehouse | H11: 식료품/생활용품 | I11: Costco 매장 | J11: Costco 매장 | K11: 5.94 | L11: =IF($E11="구매",$K11,0) | M11: =IF($E11="환불/크레딧",$K11,0) | N11: =IF($E11="결제",$K11,0) | O11: =$K11 | P11: 2026-05 | Q11: May2026_2c5d.pdf
A12: 20260501-0002 | B12: 46143 | D12: Prime Visa (Chase) ****6217 | E12: 구매 | F12: AMAZON MKTPL*BJ9771GJ1 Amzn.com/bill WA | G12: Amazon | H12: 온라인쇼핑 | I12: Amazon | J12: Amazon | K12: 15.29 | L12: =IF($E12="구매",$K12,0) | M12: =IF($E12="환불/크레딧",$K12,0) | N12: =IF($E12="결제",$K12,0) | O12: =$K12 | P12: 2026-05 | Q12: 69212C10-1B95-4A05-9104-379BBA52768F-list_d242.pdf
A13: 20260506-0003 | B13: 46148 | D13: Prime Visa (Chase) ****6217 | E13: 환불/크레딧 | F13: AMAZON MKTPLACE PMTS Amzn.com/bill WA | G13: Amazon | H13: 환불/크레딧 | I13: 환불/반품 | J13: Amazon 환불 | K13: -40.82 | L13: =IF($E13="구매",$K13,0) | M13: =IF($E13="환불/크레딧",$K13,0) | N13: =IF($E13="결제",$K13,0) | O13: =$K13 | P13: 2026-05 | Q13: 69212C10-1B95-4A05-9104-379BBA52768F-list_d242.pdf
A14: 20260509-0004 | B14: 46151 | C14: 46151 | D14: Costco Anywhere Visa (Citi) ****6858 | E14: 구매 | F14: COSTCO GAS #0484 OREM UT | G14: Costco Gas | H14: 교통/주유 | I14: 주유 | J14: Costco Gas | K14: 50.92 | L14: =IF($E14="구매",$K14,0) | M14: =IF($E14="환불/크레딧",$K14,0) | N14: =IF($E14="결제",$K14,0) | O14: =$K14 | P14: 2026-06 | Q14: June2026_4656.pdf
A15: 20260509-0005 | B15: 46151 | C15: 46151 | D15: Costco Anywhere Visa (Citi) ****6858 | E15: 구매 | F15: COSTCO WHSE #0484 OREM UT | G15: Costco Warehouse | H15: 식료품/생활용품 | I15: Costco 매장 | J15: Costco 매장 | K15: 99.89 | L15: =IF($E15="구매",$K15,0) | M15: =IF($E15="환불/크레딧",$K15,0) | N15: =IF($E15="결제",$K15,0) | O15: =$K15 | P15: 2026-06 | Q15: June2026_4656.pdf
A16: 20260509-0006 | B16: 46151 | D16: Prime Visa (Chase) ****6217 | E16: 구매 | F16: AMAZON MKTPL*BV5M29LZ0 Amzn.com/bill WA | G16: Amazon | H16: 온라인쇼핑 | I16: Amazon | J16: Amazon | K16: 6.94 | L16: =IF($E16="구매",$K16,0) | M16: =IF($E16="환불/크레딧",$K16,0) | N16: =IF($E16="결제",$K16,0) | O16: =$K16 | P16: 2026-05 | Q16: 69212C10-1B95-4A05-9104-379BBA52768F-list_d242.pdf
A17: 20260510-0007 | B17: 46152 | C17: 46152 | D17: Costco Anywhere Visa (Citi) ****6858 | E17: 구매 | F17: Nintendo CC1626816227 800-2553700 WA | G17: Nintendo | H17: 엔터테인먼트 | I17: 게임/디지털 | J17: 게임/디지털 | K17: 64.46 | L17: =IF($E17="구매",$K17,0) | M17: =IF($E17="환불/크레딧",$K17,0) | N17: =IF($E17="결제",$K17,0) | O17: =$K17 | P17: 2026-06 | Q17: June2026_4656.pdf
A18: 20260510-0008 | B18: 46152 | D18: Prime Visa (Chase) ****6217 | E18: 구매 | F18: AMAZON MKTPL*BV3ZY9YE1 Amzn.com/bill WA | G18: Amazon | H18: 온라인쇼핑 | I18: Amazon | J18: Amazon | K18: 47.36 | L18: =IF($E18="구매",$K18,0) | M18: =IF($E18="환불/크레딧",$K18,0) | N18: =IF($E18="결제",$K18,0) | O18: =$K18 | P18: 2026-05 | Q18: 69212C10-1B95-4A05-9104-379BBA52768F-list_d242.pdf
A19: 20260510-0009 | B19: 46152 | D19: Prime Visa (Chase) ****6217 | E19: 구매 | F19: AMAZON MKTPL*EY6229ND3 Amzn.com/bill WA | G19: Amazon | H19: 온라인쇼핑 | I19: Amazon | J19: Amazon | K19: 12.35 | L19: =IF($E19="구매",$K19,0) | M19: =IF($E19="환불/크레딧",$K19,0) | N19: =IF($E19="결제",$K19,0) | O19: =$K19 | P19: 2026-05 | Q19: 69212C10-1B95-4A05-9104-379BBA52768F-list_d242.pdf
A20: 20260510-0010 | B20: 46152 | D20: Prime Visa (Chase) ****6217 | E20: 구매 | F20: Amazon.com*BV9MS0AP0 Amzn.com/bill WA | G20: Amazon | H20: 온라인쇼핑 | I20: Amazon | J20: Amazon | K20: 19.1 | L20: =IF($E20="구매",$K20,0) | M20: =IF($E20="환불/크레딧",$K20,0) | N20: =IF($E20="결제",$K20,0) | O20: =$K20 | P20: 2026-05 | Q20: 69212C10-1B95-4A05-9104-379BBA52768F-list_d242.pdf
A21: 20260511-0011 | B21: 46153 | C21: 46153 | D21: Costco Anywhere Visa (Citi) ****6858 | E21: 구매 | F21: PROGRESSIVE INS 800-776-4737 OH | G21: Progressive Insurance | H21: 보험 | I21: 자동차보험 | J21: 자동차보험 | K21: 440 | L21: =IF($E21="구매",$K21,0) | M21: =IF($E21="환불/크레딧",$K21,0) | N21: =IF($E21="결제",$K21,0) | O21: =$K21 | P21: 2026-06 | Q21: June2026_4656.pdf
A22: 20260511-0012 | B22: 46153 | D22: Prime Visa (Chase) ****6217 | E22: 결제 | F22: Payment Thank You-Mobile | G22: Card Payment | H22: 결제/이체 | I22: 카드대금 결제 | J22: 카드결제 | K22: -43.59 | L22: =IF($E22="구매",$K22,0) | M22: =IF($E22="환불/크레딧",$K22,0) | N22: =IF($E22="결제",$K22,0) | O22: =$K22 | P22: 2026-05 | Q22: 69212C10-1B95-4A05-9104-379BBA52768F-list_d242.pdf
A23: 20260513-0013 | B23: 46155 | D23: Prime Visa (Chase) ****6217 | E23: 구매 | F23: Amazon.com*BF33X4XD1 Amzn.com/bill WA | G23: Amazon | H23: 온라인쇼핑 | I23: Amazon | J23: Amazon | K23: 5.45 | L23: =IF($E23="구매",$K23,0) | M23: =IF($E23="환불/크레딧",$K23,0) | N23: =IF($E23="결제",$K23,0) | O23: =$K23 | P23: 2026-05 | Q23: 69212C10-1B95-4A05-9104-379BBA52768F-list_d242.pdf
A24: 20260514-0014 | B24: 46156 | D24: Prime Visa (Chase) ****6217 | E24: 결제 | F24: Payment Thank You-Mobile | G24: Card Payment | H24: 결제/이체 | I24: 카드대금 결제 | J24: 카드결제 | K24: -122.66 | L24: =IF($E24="구매",$K24,0) | M24: =IF($E24="환불/크레딧",$K24,0) | N24: =IF($E24="결제",$K24,0) | O24: =$K24 | P24: 2026-05 | Q24: 69212C10-1B95-4A05-9104-379BBA52768F-list_d242.pdf
A25: 20260516-0015 | B25: 46158 | D25: Prime Visa (Chase) ****6217 | E25: 구매 | F25: AMAZON MKTPL*ER9F60UX3 Amzn.com/bill WA | G25: Amazon | H25: 온라인쇼핑 | I25: Amazon | J25: Amazon | K25: 10.45 | L25: =IF($E25="구매",$K25,0) | M25: =IF($E25="환불/크레딧",$K25,0) | N25: =IF($E25="결제",$K25,0) | O25: =$K25 | P25: 2026-05 | Q25: 69212C10-1B95-4A05-9104-379BBA52768F-list_d242.pdf
A26: 20260519-0016 | B26: 46161 | D26: Prime Visa (Chase) ****6217 | E26: 구매 | F26: Amazon.com*G664H3SK3 Amzn.com/bill WA | G26: Amazon | H26: 온라인쇼핑 | I26: Amazon | J26: Amazon | K26: 6.99 | L26: =IF($E26="구매",$K26,0) | M26: =IF($E26="환불/크레딧",$K26,0) | N26: =IF($E26="결제",$K26,0) | O26: =$K26 | P26: 2026-05 | Q26: 69212C10-1B95-4A05-9104-379BBA52768F-list_d242.pdf
A27: 20260520-0017 | B27: 46162 | D27: Costco Anywhere Visa (Citi) ****6858 | E27: 결제 | F27: ONLINE PAYMENT, THANK YOU | G27: Card Payment | H27: 결제/이체 | I27: 카드대금 결제 | J27: 카드결제 | K27: -718.39 | L27: =IF($E27="구매",$K27,0) | M27: =IF($E27="환불/크레딧",$K27,0) | N27: =IF($E27="결제",$K27,0) | O27: =$K27 | P27: 2026-06 | Q27: June2026_4656.pdf
A28: 20260522-0018 | B28: 46164 | D28: Prime Visa (Chase) ****6217 | E28: 구매 | F28: Amazon.com*6C6U95K13 Amzn.com/bill WA | G28: Amazon | H28: 온라인쇼핑 | I28: Amazon | J28: Amazon | K28: 14.99 | L28: =IF($E28="구매",$K28,0) | M28: =IF($E28="환불/크레딧",$K28,0) | N28: =IF($E28="결제",$K28,0) | O28: =$K28 | P28: 2026-05 | Q28: 69212C10-1B95-4A05-9104-379BBA52768F-list_d242.pdf
A29: 20260523-0019 | B29: 46165 | C29: 46165 | D29: Costco Anywhere Visa (Citi) ****6858 | E29: 구매 | F29: COSTCO GAS #0484 OREM UT | G29: Costco Gas | H29: 교통/주유 | I29: 주유 | J29: Costco Gas | K29: 55.74 | L29: =IF($E29="구매",$K29,0) | M29: =IF($E29="환불/크레딧",$K29,0) | N29: =IF($E29="결제",$K29,0) | O29: =$K29 | P29: 2026-06 | Q29: June2026_4656.pdf
A30: 20260523-0020 | B30: 46165 | C30: 46165 | D30: Costco Anywhere Visa (Citi) ****6858 | E30: 구매 | F30: COSTCO WHSE #0484 OREM UT | G30: Costco Warehouse | H30: 식료품/생활용품 | I30: Costco 매장 | J30: Costco 매장 | K30: 2.16 | L30: =IF($E30="구매",$K30,0) | M30: =IF($E30="환불/크레딧",$K30,0) | N30: =IF($E30="결제",$K30,0) | O30: =$K30 | P30: 2026-06 | Q30: June2026_4656.pdf
A31: 20260523-0021 | B31: 46165 | D31: Prime Visa (Chase) ****6217 | E31: 환불/크레딧 | F31: AMAZON MKTPLACE PMTS Amzn.com/bill WA | G31: Amazon | H31: 환불/크레딧 | I31: 환불/반품 | J31: Amazon 환불 | K31: -43.59 | L31: =IF($E31="구매",$K31,0) | M31: =IF($E31="환불/크레딧",$K31,0) | N31: =IF($E31="결제",$K31,0) | O31: =$K31 | P31: 2026-05 | Q31: 69212C10-1B95-4A05-9104-379BBA52768F-list_d242.pdf
A32: 20260523-0022 | B32: 46165 | D32: Prime Visa (Chase) ****6217 | E32: 환불/크레딧 | F32: AMAZON MKTPLACE PMTS Amzn.com/bill WA | G32: Amazon | H32: 환불/크레딧 | I32: 환불/반품 | J32: Amazon 환불 | K32: -12.35 | L32: =IF($E32="구매",$K32,0) | M32: =IF($E32="환불/크레딧",$K32,0) | N32: =IF($E32="결제",$K32,0) | O32: =$K32 | P32: 2026-05 | Q32: 69212C10-1B95-4A05-9104-379BBA52768F-list_d242.pdf
A33: 20260523-0023 | B33: 46165 | D33: Prime Visa (Chase) ****6217 | E33: 환불/크레딧 | F33: AMAZON MKTPLACE PMTS Amzn.com/bill WA | G33: Amazon | H33: 환불/크레딧 | I33: 환불/반품 | J33: Amazon 환불 | K33: -6.94 | L33: =IF($E33="구매",$K33,0) | M33: =IF($E33="환불/크레딧",$K33,0) | N33: =IF($E33="결제",$K33,0) | O33: =$K33 | P33: 2026-05 | Q33: 69212C10-1B95-4A05-9104-379BBA52768F-list_d242.pdf
A34: 20260524-0024 | B34: 46166 | D34: Prime Visa (Chase) ****6217 | E34: 구매 | F34: AMAZON MKTPL*LE8NV2TZ3 Amzn.com/bill WA | G34: Amazon | H34: 온라인쇼핑 | I34: Amazon | J34: Amazon | K34: 17.33 | L34: =IF($E34="구매",$K34,0) | M34: =IF($E34="환불/크레딧",$K34,0) | N34: =IF($E34="결제",$K34,0) | O34: =$K34 | P34: 2026-05 | Q34: 69212C10-1B95-4A05-9104-379BBA52768F-list_d242.pdf
A35: 20260524-0025 | B35: 46166 | D35: Prime Visa (Chase) ****6217 | E35: 구매 | F35: AMAZON MKTPL*YZ2086ON3 Amzn.com/bill WA | G35: Amazon | H35: 온라인쇼핑 | I35: Amazon | J35: Amazon | K35: 5.36 | L35: =IF($E35="구매",$K35,0) | M35: =IF($E35="환불/크레딧",$K35,0) | N35: =IF($E35="결제",$K35,0) | O35: =$K35 | P35: 2026-05 | Q35: 69212C10-1B95-4A05-9104-379BBA52768F-list_d242.pdf
A36: 20260527-0026 | B36: 46169 | D36: Prime Visa (Chase) ****6217 | E36: 구매 | F36: AMAZON MKTPL*R09299H43 Amzn.com/bill WA | G36: Amazon | H36: 온라인쇼핑 | I36: Amazon | J36: Amazon | K36: 26.85 | L36: =IF($E36="구매",$K36,0) | M36: =IF($E36="환불/크레딧",$K36,0) | N36: =IF($E36="결제",$K36,0) | O36: =$K36 | P36: 2026-05 | Q36: 69212C10-1B95-4A05-9104-379BBA52768F-list_d242.pdf
A37: 20260527-0027 | B37: 46169 | D37: Prime Visa (Chase) ****6217 | E37: 구매 | F37: Amazon.com*K37W61RF3 Amzn.com/bill WA | G37: Amazon | H37: 온라인쇼핑 | I37: Amazon | J37: Amazon | K37: 6.38 | L37: =IF($E37="구매",$K37,0) | M37: =IF($E37="환불/크레딧",$K37,0) | N37: =IF($E37="결제",$K37,0) | O37: =$K37 | P37: 2026-05 | Q37: 69212C10-1B95-4A05-9104-379BBA52768F-list_d242.pdf
A38: 20260527-0028 | B38: 46169 | D38: Prime Visa (Chase) ****6217 | E38: 구매 | F38: Amazon.com*L40T27973 Amzn.com/bill WA | G38: Amazon | H38: 온라인쇼핑 | I38: Amazon | J38: Amazon | K38: 22.07 | L38: =IF($E38="구매",$K38,0) | M38: =IF($E38="환불/크레딧",$K38,0) | N38: =IF($E38="결제",$K38,0) | O38: =$K38 | P38: 2026-05 | Q38: 69212C10-1B95-4A05-9104-379BBA52768F-list_d242.pdf

Sheet 06월
A1: 2026년 6월 카드 사용내역
A3: 구매 지출 합계 | B3: 0 | D3: 편집 안내 | E3: 사용자_대분류/사용자_세부분류/사용자_메모 열은 직접 수정용입니다. 원본 분류는 비교를 위해 보존했습니다.
A4: 환불/크레딧 합계 | B4: 0
A5: 카드대금 결제 합계 | B5: 0
A6: 순액 | B6: 0
A7: 거래 수 | B7: 0
A10: ID | B10: 사용일 | C10: 전기일 | D10: 카드 | E10: 거래유형 | F10: 상점/원본설명 | G10: 표준상점 | H10: 원본_대분류 | I10: 원본_세부분류 | J10: 상세태그 | K10: 원본금액 | L10: 지출금액 | M10: 환불/크레딧 | N10: 결제금액 | O10: 순액 | P10: 명세서월 | Q10: 원본파일 | R10: 사용자_대분류 | S10: 사용자_세부분류 | T10: 사용자_메모 | U10: 검토필요

Sheet 07월
A1: 2026년 7월 카드 사용내역
A3: 구매 지출 합계 | B3: 0 | D3: 편집 안내 | E3: 사용자_대분류/사용자_세부분류/사용자_메모 열은 직접 수정용입니다. 원본 분류는 비교를 위해 보존했습니다.
A4: 환불/크레딧 합계 | B4: 0
A5: 카드대금 결제 합계 | B5: 0
A6: 순액 | B6: 0
A7: 거래 수 | B7: 0
A10: ID | B10: 사용일 | C10: 전기일 | D10: 카드 | E10: 거래유형 | F10: 상점/원본설명 | G10: 표준상점 | H10: 원본_대분류 | I10: 원본_세부분류 | J10: 상세태그 | K10: 원본금액 | L10: 지출금액 | M10: 환불/크레딧 | N10: 결제금액 | O10: 순액 | P10: 명세서월 | Q10: 원본파일 | R10: 사용자_대분류 | S10: 사용자_세부분류 | T10: 사용자_메모 | U10: 검토필요

Sheet 08월
A1: 2026년 8월 카드 사용내역
A3: 구매 지출 합계 | B3: 0 | D3: 편집 안내 | E3: 사용자_대분류/사용자_세부분류/사용자_메모 열은 직접 수정용입니다. 원본 분류는 비교를 위해 보존했습니다.
A4: 환불/크레딧 합계 | B4: 0
A5: 카드대금 결제 합계 | B5: 0
A6: 순액 | B6: 0
A7: 거래 수 | B7: 0
A10: ID | B10: 사용일 | C10: 전기일 | D10: 카드 | E10: 거래유형 | F10: 상점/원본설명 | G10: 표준상점 | H10: 원본_대분류 | I10: 원본_세부분류 | J10: 상세태그 | K10: 원본금액 | L10: 지출금액 | M10: 환불/크레딧 | N10: 결제금액 | O10: 순액 | P10: 명세서월 | Q10: 원본파일 | R10: 사용자_대분류 | S10: 사용자_세부분류 | T10: 사용자_메모 | U10: 검토필요

Sheet 09월
A1: 2026년 9월 카드 사용내역
A3: 구매 지출 합계 | B3: 0 | D3: 편집 안내 | E3: 사용자_대분류/사용자_세부분류/사용자_메모 열은 직접 수정용입니다. 원본 분류는 비교를 위해 보존했습니다.
A4: 환불/크레딧 합계 | B4: 0
A5: 카드대금 결제 합계 | B5: 0
A6: 순액 | B6: 0
A7: 거래 수 | B7: 0
A10: ID | B10: 사용일 | C10: 전기일 | D10: 카드 | E10: 거래유형 | F10: 상점/원본설명 | G10: 표준상점 | H10: 원본_대분류 | I10: 원본_세부분류 | J10: 상세태그 | K10: 원본금액 | L10: 지출금액 | M10: 환불/크레딧 | N10: 결제금액 | O10: 순액 | P10: 명세서월 | Q10: 원본파일 | R10: 사용자_대분류 | S10: 사용자_세부분류 | T10: 사용자_메모 | U10: 검토필요

Sheet 10월
A1: 2026년 10월 카드 사용내역
A3: 구매 지출 합계 | B3: 0 | D3: 편집 안내 | E3: 사용자_대분류/사용자_세부분류/사용자_메모 열은 직접 수정용입니다. 원본 분류는 비교를 위해 보존했습니다.
A4: 환불/크레딧 합계 | B4: 0
A5: 카드대금 결제 합계 | B5: 0
A6: 순액 | B6: 0
A7: 거래 수 | B7: 0
A10: ID | B10: 사용일 | C10: 전기일 | D10: 카드 | E10: 거래유형 | F10: 상점/원본설명 | G10: 표준상점 | H10: 원본_대분류 | I10: 원본_세부분류 | J10: 상세태그 | K10: 원본금액 | L10: 지출금액 | M10: 환불/크레딧 | N10: 결제금액 | O10: 순액 | P10: 명세서월 | Q10: 원본파일 | R10: 사용자_대분류 | S10: 사용자_세부분류 | T10: 사용자_메모 | U10: 검토필요

Sheet 11월
A1: 2026년 11월 카드 사용내역
A3: 구매 지출 합계 | B3: 0 | D3: 편집 안내 | E3: 사용자_대분류/사용자_세부분류/사용자_메모 열은 직접 수정용입니다. 원본 분류는 비교를 위해 보존했습니다.
A4: 환불/크레딧 합계 | B4: 0
A5: 카드대금 결제 합계 | B5: 0
A6: 순액 | B6: 0
A7: 거래 수 | B7: 0
A10: ID | B10: 사용일 | C10: 전기일 | D10: 카드 | E10: 거래유형 | F10: 상점/원본설명 | G10: 표준상점 | H10: 원본_대분류 | I10: 원본_세부분류 | J10: 상세태그 | K10: 원본금액 | L10: 지출금액 | M10: 환불/크레딧 | N10: 결제금액 | O10: 순액 | P10: 명세서월 | Q10: 원본파일 | R10: 사용자_대분류 | S10: 사용자_세부분류 | T10: 사용자_메모 | U10: 검토필요

Sheet 12월
A1: 2026년 12월 카드 사용내역
A3: 구매 지출 합계 | B3: 0 | D3: 편집 안내 | E3: 사용자_대분류/사용자_세부분류/사용자_메모 열은 직접 수정용입니다. 원본 분류는 비교를 위해 보존했습니다.
A4: 환불/크레딧 합계 | B4: 0
A5: 카드대금 결제 합계 | B5: 0
A6: 순액 | B6: 0
A7: 거래 수 | B7: 0
A10: ID | B10: 사용일 | C10: 전기일 | D10: 카드 | E10: 거래유형 | F10: 상점/원본설명 | G10: 표준상점 | H10: 원본_대분류 | I10: 원본_세부분류 | J10: 상세태그 | K10: 원본금액 | L10: 지출금액 | M10: 환불/크레딧 | N10: 결제금액 | O10: 순액 | P10: 명세서월 | Q10: 원본파일 | R10: 사용자_대분류 | S10: 사용자_세부분류 | T10: 사용자_메모 | U10: 검토필요

Sheet 2025이월거래
A1: 2025년 사용일 거래 - 2026년 1월 명세서에 포함
A3: 구매 지출 합계 | B3: =SUM(L11:L13) | D3: 편집 안내 | E3: 사용자_대분류/사용자_세부분류/사용자_메모 열은 직접 수정용입니다. 원본 분류는 비교를 위해 보존했습니다.
A4: 환불/크레딧 합계 | B4: =SUM(M11:M13)
A5: 카드대금 결제 합계 | B5: =SUM(N11:N13)
A6: 순액 | B6: =SUM(O11:O13)
A7: 거래 수 | B7: 3
A10: ID | B10: 사용일 | C10: 전기일 | D10: 카드 | E10: 거래유형 | F10: 상점/원본설명 | G10: 표준상점 | H10: 원본_대분류 | I10: 원본_세부분류 | J10: 상세태그 | K10: 원본금액 | L10: 지출금액 | M10: 환불/크레딧 | N10: 결제금액 | O10: 순액 | P10: 명세서월 | Q10: 원본파일 | R10: 사용자_대분류 | S10: 사용자_세부분류 | T10: 사용자_메모 | U10: 검토필요
A11: 20251209-0001 | B11: 46000 | C11: 46000 | D11: Costco Anywhere Visa (Citi) ****6858 | E11: 구매 | F11: COSTCO WHSE #0484 OREM UT | G11: Costco Warehouse | H11: 식료품/생활용품 | I11: Costco 매장 | J11: Costco 매장 | K11: 54.36 | L11: =IF($E11="구매",$K11,0) | M11: =IF($E11="환불/크레딧",$K11,0) | N11: =IF($E11="결제",$K11,0) | O11: =$K11 | P11: 2026-01 | Q11: January2026_f0b0.pdf
A12: 20251216-0002 | B12: 46007 | C12: 46007 | D12: Costco Anywhere Visa (Citi) ****6858 | E12: 구매 | F12: COSTCO GAS #0484 OREM UT | G12: Costco Gas | H12: 교통/주유 | I12: 주유 | J12: Costco Gas | K12: 24.43 | L12: =IF($E12="구매",$K12,0) | M12: =IF($E12="환불/크레딧",$K12,0) | N12: =IF($E12="결제",$K12,0) | O12: =$K12 | P12: 2026-01 | Q12: January2026_f0b0.pdf
A13: 20251220-0003 | B13: 46011 | C13: 46011 | D13: Costco Anywhere Visa (Citi) ****6858 | E13: 구매 | F13: COSTCO WHSE #0484 OREM UT | G13: Costco Warehouse | H13: 식료품/생활용품 | I13: Costco 매장 | J13: Costco 매장 | K13: 65.52 | L13: =IF($E13="구매",$K13,0) | M13: =IF($E13="환불/크레딧",$K13,0) | N13: =IF($E13="결제",$K13,0) | O13: =$K13 | P13: 2026-01 | Q13: January2026_f0b0.pdf

Sheet 원본_명세서요약
A1: 원본파일 | B1: 카드 | C1: 명세서월 | D1: 시작일 | E1: 종료일 | F1: 명세서 구매합계 | G1: 추출 구매합계 | H1: 차이 | I1: 추출 환불/크레딧 | J1: 추출 결제 | K1: 거래 수
A2: January2026_f0b0.pdf | B2: Costco Anywhere Visa (Citi) ****6858 | C2: 2026-01 | D2: 45996 | E2: 46028 | F2: 267.25 | G2: 267.25 | H2: =G2-F2 | I2: 0 | J2: -406.15 | K2: 6
A3: February2026_f8d6.pdf | B3: Costco Anywhere Visa (Citi) ****6858 | C3: 2026-02 | D3: 46029 | E3: 46058 | F3: 203.95 | G3: 203.95 | H3: =G3-F3 | I3: 0 | J3: -162.37 | K3: 7
A4: March2026_da89.pdf | B4: Costco Anywhere Visa (Citi) ****6858 | C4: 2026-03 | D4: 46059 | E4: 46086 | F4: 553.37 | G4: 553.37 | H4: =G4-F4 | I4: -32.21 | J4: -380.69 | K4: 7
A5: April2026_4952.pdf | B5: Costco Anywhere Visa (Citi) ****6858 | C5: 2026-04 | D5: 46087 | E5: 46118 | F5: 339.32 | G5: 339.32 | H5: =G5-F5 | I5: 0 | J5: -438.11 | K5: 8
A6: May2026_2c5d.pdf | B6: Costco Anywhere Visa (Citi) ****6858 | C6: 2026-05 | D6: 46119 | E6: 46148 | F6: 353.5 | G6: 353.5 | H6: =G6-F6 | I6: 0 | J6: -365.66 | K6: 8
A7: June2026_4656.pdf | B7: Costco Anywhere Visa (Citi) ****6858 | C7: 2026-06 | D7: 46149 | E7: 46177 | F7: 713.17 | G7: 713.17 | H7: =G7-F7 | I7: 0 | J7: -718.39 | K7: 7
A8: F25604AB-F6FC-4AC2-96CD-5E3363840815-list_adc9.pdf | B8: Prime Visa (Chase) ****6217 | C8: 2026-01 | D8: 46020 | E8: 46050 | F8: 0 | G8: 0 | H8: =G8-F8 | I8: 0 | J8: 0 | K8: 0
A9: B3CDA793-1958-4FE0-A464-444F7501BD7F-list_3284.pdf | B9: Prime Visa (Chase) ****6217 | C9: 2026-02 | D9: 46051 | E9: 46081 | F9: 0.53 | G9: 0.53 | H9: =G9-F9 | I9: 0 | J9: 0 | K9: 1
A10: 36C0F7B9-D67A-4AE6-9684-B5F848CBA9D5-list_4699.pdf | B10: Prime Visa (Chase) ****6217 | C10: 2026-03 | D10: 46082 | E10: 46109 | F10: 37.6 | G10: 37.6 | H10: =G10-F10 | I10: 0 | J10: 0 | K10: 1
A11: BE3F4263-FAF2-4A9C-87A5-53852C30604D-list_09af.pdf | B11: Prime Visa (Chase) ****6217 | C11: 2026-04 | D11: 46110 | E11: 46140 | F11: 204.69 | G11: 204.69 | H11: =G11-F11 | I11: -9.19 | J11: -120.95 | K11: 13
A12: 69212C10-1B95-4A05-9104-379BBA52768F-list_d242.pdf | B12: Prime Visa (Chase) ****6217 | C12: 2026-05 | D12: 46141 | E12: 46170 | F12: 233.08 | G12: 233.08 | H12: =G12-F12 | I12: -103.7 | J12: -166.25 | K12: 21
